<?xml version="1.0" encoding="utf-8"?>

<robot name="dog" xmlns:xacro="http://www.ros.org/wiki/xacro"> 

	<material name="black">
		<color rgba="0.0 0.0 0.0 1.0"/>
	</material>
	<material name="blue">
		<color rgba="0.0 0.0 0.8 1.0"/>
	</material>
	<material name="green">
		<color rgba="0.0 0.8 0.0 1.0"/>
	</material>
	<material name="grey">
		<color rgba="0.2 0.2 0.2 1.0"/>
	</material>
	<material name="silver">
		<color rgba="0.913725490196 0.913725490196 0.847058823529 1.0"/>
	</material>
	<material name="orange">
		<color rgba="1.0 0.423529411765 0.0392156862745 1.0"/>
	</material>
	<material name="brown">
		<color rgba="0.870588235294 0.811764705882 0.764705882353 1.0"/>
	</material>
	<material name="red">
		<color rgba="0.8 0.0 0.0 1.0"/>
	</material>
	<material name="white">
		<color rgba="1.0 1.0 1.0 1.0"/>
	</material>

	<!-- =================================================================================== -->
	<!-- ros_control plugin -->
	<!-- =================================================================================== -->
	<gazebo>
		<plugin filename="libgazebo_ros_control.so" name="gazebo_ros_control">
		<robotNamespace>/dog</robotNamespace>
		<robotSimType>gazebo_ros_control/DefaultRobotHWSim</robotSimType>
		</plugin>
	</gazebo>

	<!-- =================================================================================== -->
	<!-- Show the trajectory of trunk center. -->
	<!-- =================================================================================== -->
	<gazebo>
		<plugin filename="libLinkPlot3DPlugin.so" name="3dplotTrunk">
		<frequency>10</frequency>
		<plot>
			<link>base</link>
			<pose>0 0 0 0 0 0</pose>
			<material>Gazebo/Yellow</material>
		</plot>
		</plugin>
	</gazebo>

	<!-- =================================================================================== -->
	<gazebo>
		<plugin filename="libgazebo_ros_force.so" name="gazebo_ros_force">
		<bodyName>trunk</bodyName>
		<topicName>/apply_force/trunk</topicName>
		</plugin>
	</gazebo>
	
	<gazebo reference="imu_link">
		<gravity>true</gravity>
		<sensor name="imu_sensor" type="imu">
		<always_on>true</always_on>
		<update_rate>1000</update_rate>
		<visualize>true</visualize>
		<topic>__default_topic__</topic>
		<plugin filename="libgazebo_ros_imu_sensor.so" name="imu_plugin">
			<topicName>trunk_imu</topicName>
			<bodyName>imu_link</bodyName>
			<updateRateHZ>1000.0</updateRateHZ>
			<gaussianNoise>0.0</gaussianNoise>
			<xyzOffset>0 0 0</xyzOffset>
			<rpyOffset>0 0 0</rpyOffset>
			<frameName>imu_link</frameName>
		</plugin>
		<pose>0 0 0 0 0 0</pose>
		</sensor>
	</gazebo>
	
	<!-- =================================================================================== -->
	<!-- Foot contacts. -->
	<!-- =================================================================================== -->
	<gazebo reference="FR_calf">
		<sensor name="FR_foot_contact" type="contact">
		<update_rate>100</update_rate>
		<plugin filename="libunitreeFootContactPlugin.so" name="contactPlugin"/>
		<contact>
			<collision>FR_calf_fixed_joint_lump__FR_foot_collision_1</collision>
		</contact>
		</sensor>
	</gazebo>
	
	<gazebo reference="FL_calf">
		<sensor name="FL_foot_contact" type="contact">
		<update_rate>100</update_rate>
		<plugin filename="libunitreeFootContactPlugin.so" name="contactPlugin"/>
		<contact>
			<collision>FL_calf_fixed_joint_lump__FL_foot_collision_1</collision>
		</contact>
		</sensor>
	</gazebo>
	
	<gazebo reference="RR_calf">
		<sensor name="RR_foot_contact" type="contact">
		<update_rate>100</update_rate>
		<plugin filename="libunitreeFootContactPlugin.so" name="contactPlugin"/>
		<contact>
			<collision>RR_calf_fixed_joint_lump__RR_foot_collision_1</collision>
		</contact>
		</sensor>
	</gazebo>
	
	<gazebo reference="RL_calf">
		<sensor name="RL_foot_contact" type="contact">
		<update_rate>100</update_rate>
		<plugin filename="libunitreeFootContactPlugin.so" name="contactPlugin"/>
		<contact>
			<collision>RL_calf_fixed_joint_lump__RL_foot_collision_1</collision>
		</contact>
		</sensor>
	</gazebo>
	
	<!-- =================================================================================== -->
	<!-- Visualization of Foot contacts. -->
	<!-- =================================================================================== -->
	<gazebo reference="FR_foot">
		<visual>
		<plugin filename="libunitreeDrawForcePlugin.so" name="drawForcePlugin">
			<topicName>FR_foot_contact</topicName>
		</plugin>
		</visual>
	</gazebo>
	
	<gazebo reference="FL_foot">
		<visual>
		<plugin filename="libunitreeDrawForcePlugin.so" name="drawForcePlugin">
			<topicName>FL_foot_contact</topicName>
		</plugin>
		</visual>
	</gazebo>
	
	<gazebo reference="RR_foot">
		<visual>
		<plugin filename="libunitreeDrawForcePlugin.so" name="drawForcePlugin">
			<topicName>RR_foot_contact</topicName>
		</plugin>
		</visual>
	</gazebo>
	
	<gazebo reference="RL_foot">
		<visual>
		<plugin filename="libunitreeDrawForcePlugin.so" name="drawForcePlugin">
			<topicName>RL_foot_contact</topicName>
		</plugin>
		</visual>
	</gazebo>
	
	<!-- =================================================================================== -->
	<gazebo reference="base">
		<material>Gazebo/Green</material>
		<turnGravityOff>false</turnGravityOff>
	</gazebo>
	
	<gazebo reference="trunk">
		<mu1>0.2</mu1>
		<mu2>0.2</mu2>
		<kp value="1000000.0"/>
		<kd value="1.0"/>
	</gazebo>
	
	<gazebo reference="stick_link">
		<mu1>0.2</mu1>
		<mu2>0.2</mu2>
		<material>Gazebo/White</material>
	</gazebo>
	
	<gazebo reference="imu_link">
		<mu1>0.2</mu1>
		<mu2>0.2</mu2>
		<material>Gazebo/Red</material>
	</gazebo>
	
	<!-- FL leg -->
	<gazebo reference="FL_hip">
		<mu1>0.2</mu1>
		<mu2>0.2</mu2>
		<material>Gazebo/DarkGrey</material>
	</gazebo>
	
	<gazebo reference="FL_thigh">
		<mu1>0.2</mu1>
		<mu2>0.2</mu2>
		<self_collide>1</self_collide>
		<material>Gazebo/DarkGrey</material>
		<kp value="1000000.0"/>
		<kd value="1.0"/>
	</gazebo>
	
	<gazebo reference="FL_calf">
		<mu1>0.2</mu1>
		<mu2>0.2</mu2>
		<self_collide>1</self_collide>
	</gazebo>
	
	<gazebo reference="FL_foot">
		<mu1>1</mu1>
		<mu2>1</mu2>
		<self_collide>1</self_collide>
		<material>Gazebo/DarkGrey</material>
		<kp value="1000000.0"/>
		<kd value="1.0"/>
	</gazebo>
	
	<!-- FR leg -->
	<gazebo reference="FR_hip">
		<mu1>0.2</mu1>
		<mu2>0.2</mu2>
		<material>Gazebo/DarkGrey</material>
	</gazebo>
	
	<gazebo reference="FR_thigh">
		<mu1>0.2</mu1>
		<mu2>0.2</mu2>
		<self_collide>1</self_collide>
		<material>Gazebo/DarkGrey</material>
		<kp value="1000000.0"/>
		<kd value="1.0"/>
	</gazebo>
	
	<gazebo reference="FR_calf">
		<mu1>0.2</mu1>
		<mu2>0.2</mu2>
		<self_collide>1</self_collide>
	</gazebo>
	
	<gazebo reference="FR_foot">
		<mu1>1</mu1>
		<mu2>1</mu2>
		<self_collide>1</self_collide>
		<material>Gazebo/DarkGrey</material>
		<kp value="1000000.0"/>
		<kd value="1.0"/>
	</gazebo>
	
	<!-- RL leg -->
	<gazebo reference="RL_hip">
		<mu1>0.2</mu1>
		<mu2>0.2</mu2>
		<material>Gazebo/DarkGrey</material>
	</gazebo>
	
	<gazebo reference="RL_thigh">
		<mu1>0.2</mu1>
		<mu2>0.2</mu2>
		<self_collide>1</self_collide>
		<material>Gazebo/DarkGrey</material>
		<kp value="1000000.0"/>
		<kd value="1.0"/>
	</gazebo>
	
	<gazebo reference="RL_calf">
		<mu1>0.2</mu1>
		<mu2>0.2</mu2>
		<self_collide>1</self_collide>
	</gazebo>
	
	<gazebo reference="RL_foot">
		<mu1>1</mu1>
		<mu2>1</mu2>
		<self_collide>1</self_collide>
		<material>Gazebo/DarkGrey</material>
		<kp value="1000000.0"/>
		<kd value="1.0"/>
	</gazebo>
	
	<!-- RR leg -->
	<gazebo reference="RR_hip">
		<mu1>0.2</mu1>
		<mu2>0.2</mu2>
		<material>Gazebo/DarkGrey</material>
	</gazebo>
	
	<gazebo reference="RR_thigh">
		<mu1>0.2</mu1>
		<mu2>0.2</mu2>
		<self_collide>1</self_collide>
		<material>Gazebo/DarkGrey</material>
		<kp value="1000000.0"/>
		<kd value="1.0"/>
	</gazebo>
	
	<gazebo reference="RR_calf">
		<mu1>0.2</mu1>
		<mu2>0.2</mu2>
		<self_collide>1</self_collide>
	</gazebo>
	
	<gazebo reference="RR_foot">
		<mu1>1</mu1>
		<mu2>1</mu2>
		<self_collide>1</self_collide>
		<material>Gazebo/DarkGrey</material>
		<kp value="1000000.0"/>
		<kd value="1.0"/>
	</gazebo>
	<!-- =================================================================================== -->

	<!-- =================================================================================== -->
	<!-- Debug mode will hung up the robot, use "true" or "false" to switch it. -->
    <xacro:if value="$(arg DEBUG)">
        <link name="world"/>
        <joint name="base_static_joint" type="fixed">
            <origin rpy="0 0 0" xyz="0 0 0"/>
            <parent link="world"/>
            <child link="base"/>
        </joint>
    </xacro:if> 
    
	<link 
		name="base">
		<visual>
			<origin 
				rpy="0 0 0" 
				xyz="0 0 0"/>
			<geometry>
				<box 
				size="0.001 0.001 0.001"/>
			</geometry>
		</visual>
	</link>
	
	<joint 
		name="floating_base" 
		type="fixed">
		<origin 
			rpy="0 0 0" 
			xyz="0 0 0"/>
		<parent 
			link="base"/>
		<child 
			link="trunk"/>
	</joint>
	
	<link
		name="trunk">
		<inertial>
			<origin
				xyz="0 0 0"
				rpy="0 0 0" />
			<mass
				value="5.369" />
			<inertia
				ixx="0.014018"
				ixy="-9.8764E-10"
				ixz="2.189E-06"
				iyy="0.022916"
				iyz="-1.0695E-05"
				izz="0.031536" />
		</inertial>
		<visual>
			<origin
				xyz="0 0 0"
				rpy="0 0 0" />
			<geometry>
				<mesh
				filename="package://dog/meshes/trunk.dae" />
			</geometry>
			<material
				name="">
				<color
				rgba="0.75294 0.75294 0.75294 1" />
			</material>
		</visual>
		<collision>
			<origin
				xyz="0 0 0"
				rpy="0 0 0" />
			<geometry>
				<box size="0.425 0.3 0.125"/>
			</geometry>
		</collision>
	</link>
	<!-- =================================================================================== -->
	
	<!-- =================================================================================== -->
	<joint name="imu_joint" type="fixed">
		<parent link="trunk"/>
		<child link="imu_link"/>
		<origin rpy="0 0 0" xyz="0 0 0"/>
	</joint>
	
	<link name="imu_link">
		<inertial>
			<mass value="0.001"/>
			<origin rpy="0 0 0" xyz="0 0 0"/>
			<inertia ixx="0.0001" ixy="0" ixz="0" iyy="0.0001" iyz="0" izz="0.0001"/>
		</inertial>
		<visual>
			<origin rpy="0 0 0" xyz="0 0 0"/>
			<geometry>
				<box size="0.001 0.001 0.001"/>
			</geometry>
			<material name="red"/>
		</visual>
		<collision>
			<origin rpy="0 0 0" xyz="0 0 0"/>
			<geometry>
				<box size=".001 .001 .001"/>
			</geometry>
		</collision>
	</link>

	<!-- =================================================================================== -->
	<!-- FL leg -->
	<!-- =================================================================================== -->
	<joint
		name="FL_hip_joint"
		type="revolute">
		<origin
			xyz="0.27491 0.099829 0.0023126"
			rpy="0 0 0" />
		<parent
			link="trunk" />
		<child
			link="FL_hip" />
		<axis
			xyz="1 0 0" />
		<limit
			lower="-3.1416"
			upper="3.1416"
			effort="33.5"
			velocity="21" />
		<dynamics
			damping="0.01"
			friction="0.2" />
	</joint>
	
	<link
		name="FL_hip">
		<inertial>
			<origin
        		xyz="-0.00692304963835766 -0.0130799503639591 8.77287418627609E-06"
				rpy="0 0 0" />
			<mass
				value="0.337524542203421" />
			<inertia
				ixx="0.000215254092407494"
				ixy="2.15638092567625E-07"
				ixz="-6.84399658609385E-08"
				iyy="0.000431326436958549"
				iyz="5.16536960133808E-08"
				izz="0.00027557090454781" />
		</inertial>
		<visual>
			<origin
				xyz="0 0 0"
				rpy="0 0 0" />
			<geometry>
				<mesh
				filename="package://dog/meshes/FL_hip.dae" />
			</geometry>
				<material
					name="">
					<color
					rgba="0.752941176470588 0.752941176470588 0.752941176470588 1" />
				</material>
		</visual>
		<collision>
			<origin
				xyz="0 0 0"
				rpy="1.57079632679 0 0" />
			<geometry>
				<cylinder length="0.0437" radius="0.04825"/>
			</geometry>
		</collision>
	</link>
	
	<joint
		name="FL_thigh_joint"
		type="revolute">
		<origin
			xyz="0 0.07555 0"
			rpy="0 0 0" />
		<parent
			link="FL_hip" />
		<child
			link="FL_thigh" />
		<axis
			xyz="0 1 0" />
		<limit
			lower="-3.1416"
			upper="3.1416"
			effort="33.5"
			velocity="21" />
		<dynamics
			damping="0.01"
			friction="0.2" />
	</joint>
	
	<link
		name="FL_thigh">
		<inertial>
			<origin
				xyz="-0.00162647906680141 -0.0211042231509579 -0.0414216512995833"
				rpy="0 0 0" />
			<mass
				value="0.752071036497917" />
			<inertia
				ixx="0.00115368399686359"
				ixy="-5.15161781505904E-08"
				ixz="3.94366142837055E-06"
				iyy="0.00143053814691974"
				iyz="2.21188881777564E-06"
				izz="0.000359763371789606" />
		</inertial>
		<visual>
			<origin
				xyz="0 0 0"
				rpy="0 0 0" />
			<geometry>
				<mesh
				filename="package://dog/meshes/FL_thigh.dae" />
			</geometry>
			<material
				name="">
				<color
				rgba="0.752941176470588 0.752941176470588 0.752941176470588 1" />
			</material>
		</visual>
		<collision>
			<origin
				xyz="0 0 -0.1075"
				rpy="0 1.57079632679 0" />
			<geometry>
				<box size="0.281 0.084 0.04825"/>
			</geometry>
		</collision>
	</link>
	
	<joint
		name="FL_calf_joint"
		type="revolute">
		<origin
			xyz="0 -0.00025 -0.215"
			rpy="0 0 0" />
		<parent
			link="FL_thigh" />
		<child
			link="FL_calf" />
		<axis
			xyz="0 1 0" />
		<limit
			lower="-3.1416"
			upper="3.1416"
			effort="33.5"
			velocity="21" />
		<dynamics
			damping="0.01"
			friction="0.2" />
	</joint>

	<link
		name="FL_calf">
		<inertial>
			<origin
				xyz="-3.94060146965969E-06 -0.000200469779456536 -0.112543621491278"
				rpy="0 0 0" />
			<mass
				value="0.124258894329163" />
			<inertia
				ixx="0.00013902953204446"
				ixy="1.33749908628396E-12"
				ixz="-2.74121697814619E-10"
				iyy="0.000145283524562499"
				iyz="4.05270232077448E-07"
				izz="1.81938767558011E-05" />
		</inertial>
		<visual>
			<origin
				xyz="0 0 0"
				rpy="0 0 0" />
			<geometry>
				<mesh
				filename="package://dog/meshes/FL_calf.dae" />
			</geometry>
			<material
				name="">
				<color
				rgba="0.752941176470588 0.752941176470588 0.752941176470588 1" />
			</material>
		</visual>
		<collision>
			<origin
				xyz="0 0 -0.1136"
				rpy="0 1.57079632679 0" />
			<geometry>
				<box size="0.251 0.0238 0.021"/>
			</geometry>
		</collision>
	</link>

	<joint name="FL_foot_fixed" type="fixed">
		<origin rpy="0 0 0" xyz="0 0 -0.2172"/>
		<parent link="FL_calf"/>
		<child link="FL_foot"/>
	</joint>
	
	<link name="FL_foot">
		<visual>
			<origin rpy="0 0 0" xyz="0 0 0"/>
			<geometry>
				<sphere radius="0.01"/>
			</geometry>
			<material name="orange"/>
		</visual>
		<collision>
			<origin rpy="0 0 0" xyz="0 0 0"/>
			<geometry>
				<sphere radius="0.01"/>
			</geometry>
		</collision>
		<inertial>
			<mass value="0.06"/>
			<inertia ixx="9.6e-06" ixy="0.0" ixz="0.0" iyy="9.6e-06" iyz="0.0" izz="9.6e-06"/>
		</inertial>
	</link>

	<transmission name="FL_hip_tran">
		<type>transmission_interface/SimpleTransmission</type>
		<joint name="FL_hip_joint">
			<hardwareInterface>hardware_interface/EffortJointInterface</hardwareInterface>
		</joint>
		<actuator name="FL_hip_motor">
			<hardwareInterface>hardware_interface/EffortJointInterface</hardwareInterface>
			<mechanicalReduction>1</mechanicalReduction>
		</actuator>
	</transmission>
	
	<transmission name="FL_thigh_tran">
		<type>transmission_interface/SimpleTransmission</type>
		<joint name="FL_thigh_joint">
			<hardwareInterface>hardware_interface/EffortJointInterface</hardwareInterface>
		</joint>
		<actuator name="FL_thigh_motor">
			<hardwareInterface>hardware_interface/EffortJointInterface</hardwareInterface>
			<mechanicalReduction>1</mechanicalReduction>
		</actuator>
	</transmission>
	
	<transmission name="FL_calf_tran">
		<type>transmission_interface/SimpleTransmission</type>
		<joint name="FL_calf_joint">
			<hardwareInterface>hardware_interface/EffortJointInterface</hardwareInterface>
		</joint>
		<actuator name="FL_calf_motor">
			<hardwareInterface>hardware_interface/EffortJointInterface</hardwareInterface>
			<mechanicalReduction>1</mechanicalReduction>
		</actuator>
	</transmission>

	<!-- =================================================================================== -->  
	<!-- FR leg -->
	<!-- =================================================================================== -->
	<joint
		name="FR_hip_joint"
		type="revolute">
		<origin
			xyz="0.27491 -0.10017 0.0023126"
			rpy="0 0 0" />
		<parent
			link="trunk" />
		<child
			link="FR_hip" />
		<axis
			xyz="1 0 0" />
		<limit
			lower="-3.1416"
			upper="3.1416"
			effort="33.5"
			velocity="21" />
		<dynamics
			damping="0.01"
			friction="0.2" />
	</joint>

	<link
		name="FR_hip">
		<inertial>
			<origin
				xyz="-0.0069230496383576 0.0130799503639589 -8.77287418629647E-06"
				rpy="0 0 0" />
			<mass
				value="0.337524542203421" />
			<inertia
				ixx="0.000215254092407494"
				ixy="2.15638092567625E-07"
				ixz="-6.84399658609385E-08"
				iyy="0.000431326436958549"
				iyz="5.16536960133808E-08"
				izz="0.00027557090454781" />
		</inertial>
		<visual>
			<origin
				xyz="0 0 0"
				rpy="0 0 0" />
			<geometry>
				<mesh
				filename="package://dog/meshes/FR_hip.dae" />
			</geometry>
			<material
				name="">
				<color
				rgba="0.752941176470588 0.752941176470588 0.752941176470588 1" />
			</material>
		</visual>
		<collision>
			<origin
				xyz="0 0 0"
				rpy="1.57079632679 0 0" />
			<geometry>
				<cylinder length="0.0437" radius="0.04825"/>
			</geometry>
		</collision>
	</link>

	<joint
		name="FR_thigh_joint"
		type="revolute">
		<origin
			xyz="0 -0.07555 0"
			rpy="0 0 0" />
		<parent
			link="FR_hip" />
		<child
			link="FR_thigh" />
		<axis
			xyz="0 1 0" />
		<limit
			lower="-3.1416"
			upper="3.1416"
			effort="33.5"
			velocity="21" />
		<dynamics
			damping="0.01"
			friction="0.2" />
	</joint>
	
	<link
		name="FR_thigh">
		<inertial>
			<origin
				xyz="-0.00170171026708282 0.0211066364397727 -0.0414030033466159"
				rpy="0 0 0" />
			<mass
				value="0.752071036497917" />
			<inertia
				ixx="0.00115368399686359"
				ixy="-5.15161781505904E-08"
				ixz="3.94366142837055E-06"
				iyy="0.00143053814691974"
				iyz="2.21188881777564E-06"
				izz="0.000359763371789606" />
		</inertial>
		<visual>
			<origin
				xyz="0 0 0"
				rpy="0 0 0" />
			<geometry>
				<mesh
				filename="package://dog/meshes/FR_thigh.dae" />
			</geometry>
			<material
				name="">
				<color
				rgba="0.752941176470588 0.752941176470588 0.752941176470588 1" />
			</material>
		</visual>
		<collision>
			<origin
				xyz="0 0 -0.1075"
				rpy="0 1.57079632679 0" />
			<geometry>
				<box size="0.281 0.084 0.04825"/>
			</geometry>
		</collision>
	</link>

	<joint
		name="FR_calf_joint"
		type="revolute">
		<origin
			xyz="0 0.00025 -0.215"
			rpy="0 0 0" />
		<parent
			link="FR_thigh" />
		<child
			link="FR_calf" />
		<axis
			xyz="0 1 0" />
		<limit
			lower="-3.1416"
			upper="3.1416"
			effort="33.5"
			velocity="21" />
		<dynamics
			damping="0.01"
			friction="0.2" />
	</joint>

	<link
		name="FR_calf">
		<inertial>
			<origin
				xyz="3.94060146979847E-06 0.000200469779456564 -0.112543621491278"
				rpy="0 0 0" />
			<mass
				value="0.124258894329163" />
			<inertia
				ixx="0.00013902953204446"
				ixy="1.33749908628396E-12"
				ixz="-2.74121697814619E-10"
				iyy="0.000145283524562499"
				iyz="4.05270232077448E-07"
				izz="1.81938767558011E-05" />
		</inertial>
		<visual>
			<origin
				xyz="0 0 0"
				rpy="0 0 0" />
			<geometry>
				<mesh
				filename="package://dog/meshes/FR_calf.dae" />
			</geometry>
			<material
				name="">
				<color
				rgba="0.752941176470588 0.752941176470588 0.752941176470588 1" />
			</material>
		</visual>
		<collision>
			<origin
				xyz="0 0 -0.1136"
				rpy="0 1.57079632679 0" />
			<geometry>
				<box size="0.251 0.0238 0.021"/>
			</geometry>
		</collision>
	</link>

	<joint name="FR_foot_fixed" type="fixed">
		<origin rpy="0 0 0" xyz="0 0 -0.2172"/>
		<parent link="FR_calf"/>
		<child link="FR_foot"/>
	</joint>
	
	<link name="FR_foot">
		<visual>
			<origin rpy="0 0 0" xyz="0 0 0"/>
			<geometry>
				<sphere radius="0.01"/>
			</geometry>
			<material name="orange"/>
		</visual>
		<collision>
			<origin rpy="0 0 0" xyz="0 0 0"/>
			<geometry>
				<sphere radius="0.01"/>
			</geometry>
		</collision>
		<inertial>
			<mass value="0.06"/>
			<inertia ixx="9.6e-06" ixy="0.0" ixz="0.0" iyy="9.6e-06" iyz="0.0" izz="9.6e-06"/>
		</inertial>
	</link>

	<transmission name="FR_hip_tran">
		<type>transmission_interface/SimpleTransmission</type>
		<joint name="FR_hip_joint">
			<hardwareInterface>hardware_interface/EffortJointInterface</hardwareInterface>
		</joint>
		<actuator name="FR_hip_motor">
			<hardwareInterface>hardware_interface/EffortJointInterface</hardwareInterface>
			<mechanicalReduction>1</mechanicalReduction>
		</actuator>
	</transmission>
	
	<transmission name="FR_thigh_tran">
		<type>transmission_interface/SimpleTransmission</type>
		<joint name="FR_thigh_joint">
			<hardwareInterface>hardware_interface/EffortJointInterface</hardwareInterface>
		</joint>
		<actuator name="FR_thigh_motor">
			<hardwareInterface>hardware_interface/EffortJointInterface</hardwareInterface>
			<mechanicalReduction>1</mechanicalReduction>
		</actuator>
	</transmission>
	
	<transmission name="FR_calf_tran">
		<type>transmission_interface/SimpleTransmission</type>
		<joint name="FR_calf_joint">
			<hardwareInterface>hardware_interface/EffortJointInterface</hardwareInterface>
		</joint>
		<actuator name="FR_calf_motor">
			<hardwareInterface>hardware_interface/EffortJointInterface</hardwareInterface>
			<mechanicalReduction>1</mechanicalReduction>
		</actuator>
	</transmission>

	<!-- =================================================================================== -->
	<!-- RL leg -->
	<!-- =================================================================================== -->  
	<joint
		name="RL_hip_joint"
		type="revolute">
		<origin
			xyz="-0.27429 0.099829 0.0023126"
			rpy="0 0 0" />
		<parent
			link="trunk" />
		<child
			link="RL_hip" />
		<axis
			xyz="1 0 0" />
		<limit
			lower="-3.1416"
			upper="3.1416"
			effort="33.5"
			velocity="21" />
		<dynamics
			damping="0.01"
			friction="0.2" />
	</joint>
	
	<link
		name="RL_hip">
		<inertial>
			<origin
				xyz="0.00692304963835755 -0.0130799503639591 -8.77287418624573E-06"
				rpy="0 0 0" />
			<mass
				value="0.337524542203421" />
			<inertia
				ixx="0.000215254092407494"
				ixy="2.15638092567625E-07"
				ixz="-6.84399658609385E-08"
				iyy="0.000431326436958549"
				iyz="5.16536960133808E-08"
				izz="0.00027557090454781" />
		</inertial>
		<visual>
			<origin
				xyz="0 0 0"
				rpy="0 0 0" />
			<geometry>
				<mesh
				filename="package://dog/meshes/RL_hip.dae" />
			</geometry>
			<material
				name="">
				<color
				rgba="0.752941176470588 0.752941176470588 0.752941176470588 1" />
			</material>
		</visual>
		<collision>
			<origin
				xyz="0 0 0"
				rpy="1.57079632679 0 0" />
			<geometry>
				<cylinder length="0.0437" radius="0.04825"/>
			</geometry>
		</collision>
	</link>
	
	<joint
		name="RL_thigh_joint"
		type="revolute">
		<origin
			xyz="0 0.07555 0"
			rpy="0 0 0" />
		<parent
			link="RL_hip" />
		<child
			link="RL_thigh" />
		<axis
			xyz="0 1 0" />
		<limit
			lower="-3.1416"
			upper="3.1416"
			effort="33.5"
			velocity="21" />
		<dynamics
			damping="0.01"
			friction="0.2" />
	</joint>

	<link
		name="RL_thigh">
		<inertial>
			<origin
				xyz="-0.00162647906680125 -0.021104223150958 -0.0414216512995832"
				rpy="0 0 0" />
			<mass
				value="0.752071036497917" />
			<inertia
				ixx="0.00115368399686359"
				ixy="-5.15161781505904E-08"
				ixz="3.94366142837055E-06"
				iyy="0.00143053814691974"
				iyz="2.21188881777564E-06"
				izz="0.000359763371789606" />
		</inertial>
		<visual>
			<origin
				xyz="0 0 0"
				rpy="0 0 0" />
			<geometry>
				<mesh
				filename="package://dog/meshes/RL_thigh.dae" />
			</geometry>
			<material
				name="">
				<color
				rgba="0.752941176470588 0.752941176470588 0.752941176470588 1" />
			</material>
		</visual>
		<collision>
			<origin
				xyz="0 0 -0.1075"
				rpy="0 1.57079632679 0" />
			<geometry>
				<box size="0.281 0.084 0.04825"/>
			</geometry>
		</collision>
	</link>
	
	<joint
		name="RL_calf_joint"
		type="revolute">
		<origin
			xyz="0 -0.00025 -0.215"
			rpy="0 0 0" />
		<parent
			link="RL_thigh" />
		<child
			link="RL_calf" />
		<axis
			xyz="0 1 0" />
		<limit
			lower="-3.1416"
			upper="3.1416"
			effort="33.5"
			velocity="21" />
		<dynamics
			damping="0.01"
			friction="0.2" />
	</joint>

	<link
		name="RL_calf">
		<inertial>
			<origin
				xyz="-3.9406014697152E-06 -0.000200469779456564 -0.112543621491278"
				rpy="0 0 0" />
			<mass
				value="0.124258894329163" />
			<inertia
				ixx="0.00013902953204446"
				ixy="1.33749908628396E-12"
				ixz="-2.74121697814619E-10"
				iyy="0.000145283524562499"
				iyz="4.05270232077448E-07"
				izz="1.81938767558011E-05" />
		</inertial>
		<visual>
			<origin
				xyz="0 0 0"
				rpy="0 0 0" />
			<geometry>
				<mesh
				filename="package://dog/meshes/RL_calf.dae" />
			</geometry>
			<material
				name="">
				<color
				rgba="0.752941176470588 0.752941176470588 0.752941176470588 1" />
			</material>
		</visual>
		<collision>
			<origin
				xyz="0 0 -0.1136"
				rpy="0 1.57079632679 0" />
			<geometry>
				<box size="0.251 0.0238 0.021"/>
			</geometry>
		</collision>
	</link>

	<joint name="RL_foot_fixed" type="fixed">
		<origin rpy="0 0 0" xyz="0 0 -0.2172"/>
		<parent link="RL_calf"/>
		<child link="RL_foot"/>
	</joint>

	<link name="RL_foot">
		<visual>
			<origin rpy="0 0 0" xyz="0 0 0"/>
			<geometry>
				<sphere radius="0.01"/>
			</geometry>
			<material name="orange"/>
		</visual>
		<collision>
			<origin rpy="0 0 0" xyz="0 0 0"/>
			<geometry>
				<sphere radius="0.01"/>
			</geometry>
		</collision>
		<inertial>
			<mass value="0.06"/>
			<inertia ixx="9.6e-06" ixy="0.0" ixz="0.0" iyy="9.6e-06" iyz="0.0" izz="9.6e-06"/>
		</inertial>
	</link>

	<transmission name="RL_hip_tran">
		<type>transmission_interface/SimpleTransmission</type>
		<joint name="RL_hip_joint">
			<hardwareInterface>hardware_interface/EffortJointInterface</hardwareInterface>
		</joint>
		<actuator name="RL_hip_motor">
			<hardwareInterface>hardware_interface/EffortJointInterface</hardwareInterface>
			<mechanicalReduction>1</mechanicalReduction>
		</actuator>
	</transmission>
	
	<transmission name="RL_thigh_tran">
		<type>transmission_interface/SimpleTransmission</type>
		<joint name="RL_thigh_joint">
			<hardwareInterface>hardware_interface/EffortJointInterface</hardwareInterface>
		</joint>
		<actuator name="RL_thigh_motor">
			<hardwareInterface>hardware_interface/EffortJointInterface</hardwareInterface>
			<mechanicalReduction>1</mechanicalReduction>
		</actuator>
	</transmission>
	
	<transmission name="RL_calf_tran">
		<type>transmission_interface/SimpleTransmission</type>
		<joint name="RL_calf_joint">
			<hardwareInterface>hardware_interface/EffortJointInterface</hardwareInterface>
		</joint>
		<actuator name="RL_calf_motor">
			<hardwareInterface>hardware_interface/EffortJointInterface</hardwareInterface>
			<mechanicalReduction>1</mechanicalReduction>
		</actuator>
	</transmission>

	<!-- =================================================================================== -->
	<!-- RR leg -->
	<!-- =================================================================================== -->
	<joint
		name="RR_hip_joint"
		type="revolute">
		<origin
			xyz="-0.27429 -0.10017 0.0023126"
			rpy="0 0 0" />
		<parent
			link="trunk" />
		<child
			link="RR_hip" />
		<axis
			xyz="1 0 0" />
		<limit
			lower="-3.1416"
			upper="3.1416"
			effort="33.5"
			velocity="21" />
		<dynamics
			damping="0.01"
			friction="0.2" />
	</joint>
	
	<link
		name="RR_hip">
		<inertial>
			<origin
				xyz="0.00692304963835749 0.0130799503639589 8.77287418626221E-06"
				rpy="0 0 0" />
			<mass
				value="0.337524542203421" />
			<inertia
				ixx="0.000215254092407494"
				ixy="2.15638092567625E-07"
				ixz="-6.84399658609385E-08"
				iyy="0.000431326436958549"
				iyz="5.16536960133808E-08"
				izz="0.00027557090454781" />
		</inertial>
		<visual>
			<origin
				xyz="0 0 0"
				rpy="0 0 0" />
			<geometry>
				<mesh
				filename="package://dog/meshes/RR_hip.dae" />
			</geometry>
			<material
				name="">
				<color
				rgba="0.752941176470588 0.752941176470588 0.752941176470588 1" />
			</material>
		</visual>
		<collision>
			<origin
				xyz="0 0 0"
				rpy="1.57079632679 0 0" />
			<geometry>
				<cylinder length="0.0437" radius="0.04825"/>
			</geometry>
		</collision>
	</link>
	
	<joint
		name="RR_thigh_joint"
		type="revolute">
		<origin
			xyz="0 -0.07555 0"
			rpy="0 0 0" />
		<parent
			link="RR_hip" />
		<child
			link="RR_thigh" />
		<axis
			xyz="0 1 0" />
		<limit
			lower="-3.1416"
			upper="3.1416"
			effort="33.5"
			velocity="21" />
		<dynamics
			damping="0.01"
			friction="0.2" />
	</joint>
	
	<link
		name="RR_thigh">
		<inertial>
			<origin
				xyz="-0.00170171026708305 0.0211066364397727 -0.0414030033466158"
				rpy="0 0 0" />
			<mass
				value="0.752071036497917" />
			<inertia
				ixx="0.00115368399686359"
				ixy="-5.15161781505904E-08"
				ixz="3.94366142837055E-06"
				iyy="0.00143053814691974"
				iyz="2.21188881777564E-06"
				izz="0.000359763371789606" />
		</inertial>
		<visual>
			<origin
				xyz="0 0 0"
				rpy="0 0 0" />
			<geometry>
				<mesh
				filename="package://dog/meshes/RR_thigh.dae" />
			</geometry>
			<material
				name="">
				<color
				rgba="0.752941176470588 0.752941176470588 0.752941176470588 1" />
			</material>
		</visual>
			<collision>
			<origin
				xyz="0 0 -0.1075"
				rpy="0 1.57079632679 0" />
			<geometry>
				<box size="0.281 0.084 0.04825"/>
			</geometry>
		</collision>
	</link>
	
	<joint
		name="RR_calf_joint"
		type="revolute">
		<origin
			xyz="0 0.00025 -0.215"
			rpy="0 0 0" />
		<parent
			link="RR_thigh" />
		<child
			link="RR_calf" />
		<axis
			xyz="0 1 0" />
		<limit
			lower="-3.1416"
			upper="3.1416"
			effort="33.5"
			velocity="21" />
		<dynamics
			damping="0.01"
			friction="0.2" />
	</joint>

	<link
		name="RR_calf">
		<inertial>
			<origin
				xyz="-3.94060146968744E-06 -0.000200469779456591 -0.112543621491278"
				rpy="0 0 0" />
			<mass
				value="0.124258894329163" />
			<inertia
				ixx="0.00013902953204446"
				ixy="1.33749908628396E-12"
				ixz="-2.74121697814619E-10"
				iyy="0.000145283524562499"
				iyz="4.05270232077448E-07"
				izz="1.81938767558011E-05" />
		</inertial>
		<visual>
			<origin
				xyz="0 0 0"
				rpy="0 0 0" />
			<geometry>
				<mesh
				filename="package://dog/meshes/RR_calf.dae" />
			</geometry>
			<material
				name="">
				<color
				rgba="0.752941176470588 0.752941176470588 0.752941176470588 1" />
			</material>
		</visual>
		<collision>
			<origin
				xyz="0 0 -0.1136"
				rpy="0 1.57079632679 0" />
			<geometry>
				<box size="0.251 0.0238 0.021"/>
			</geometry>
		</collision>
	</link>

	<joint name="RR_foot_fixed" type="fixed">
		<origin rpy="0 0 0" xyz="0 0 -0.2172"/>
		<parent link="RR_calf"/>
		<child link="RR_foot"/>
	</joint>
	
	<link name="RR_foot">
		<visual>
			<origin rpy="0 0 0" xyz="0 0 0"/>
			<geometry>
				<sphere radius="0.01"/>
			</geometry>
			<material name="orange"/>
		</visual>
		<collision>
			<origin rpy="0 0 0" xyz="0 0 0"/>
			<geometry>
				<sphere radius="0.01"/>
			</geometry>
		</collision>
		<inertial>
			<mass value="0.06"/>
			<inertia ixx="9.6e-06" ixy="0.0" ixz="0.0" iyy="9.6e-06" iyz="0.0" izz="9.6e-06"/>
		</inertial>
	</link>

	<transmission name="RR_hip_tran">
		<type>transmission_interface/SimpleTransmission</type>
		<joint name="RR_hip_joint">
			<hardwareInterface>hardware_interface/EffortJointInterface</hardwareInterface>
		</joint>
		<actuator name="RR_hip_motor">
			<hardwareInterface>hardware_interface/EffortJointInterface</hardwareInterface>
			<mechanicalReduction>1</mechanicalReduction>
		</actuator>
	</transmission>
	
	<transmission name="RR_thigh_tran">
		<type>transmission_interface/SimpleTransmission</type>
		<joint name="RR_thigh_joint">
			<hardwareInterface>hardware_interface/EffortJointInterface</hardwareInterface>
		</joint>
		<actuator name="RR_thigh_motor">
			<hardwareInterface>hardware_interface/EffortJointInterface</hardwareInterface>
			<mechanicalReduction>1</mechanicalReduction>
		</actuator>
	</transmission>
	
	<transmission name="RR_calf_tran">
		<type>transmission_interface/SimpleTransmission</type>
		<joint name="RR_calf_joint">
			<hardwareInterface>hardware_interface/EffortJointInterface</hardwareInterface>
		</joint>
		<actuator name="RR_calf_motor">
			<hardwareInterface>hardware_interface/EffortJointInterface</hardwareInterface>
			<mechanicalReduction>1</mechanicalReduction>
		</actuator>
	</transmission>
</robot>